2018-05-11 16:26:51,374 [ERROR] app.py(1761):Exception on /index [GET]
Traceback (most recent call last):
  File "d:\microblog\flask\lib\site-packages\flask\app.py", line 2292, in wsgi_app
    response = self.full_dispatch_request()
  File "d:\microblog\flask\lib\site-packages\flask\app.py", line 1815, in full_dispatch_request
    rv = self.handle_user_exception(e)
  File "d:\microblog\flask\lib\site-packages\flask\app.py", line 1718, in handle_user_exception
    reraise(exc_type, exc_value, tb)
  File "d:\microblog\flask\lib\site-packages\flask\_compat.py", line 35, in reraise
    raise value
  File "d:\microblog\flask\lib\site-packages\flask\app.py", line 1813, in full_dispatch_request
    rv = self.dispatch_request()
  File "d:\microblog\flask\lib\site-packages\flask\app.py", line 1799, in dispatch_request
    return self.view_functions[rule.endpoint](**req.view_args)
  File "d:\microblog\flask\lib\site-packages\flask_login\utils.py", line 260, in decorated_view
    return current_app.login_manager.unauthorized()
  File "d:\microblog\flask\lib\site-packages\flask_login\login_manager.py", line 175, in unauthorized
    redirect_url = make_login_url(login_view, next_url=request.url)
  File "d:\microblog\flask\lib\site-packages\flask_login\utils.py", line 112, in login_url
    base = expand_login_view(login_view)
  File "d:\microblog\flask\lib\site-packages\flask_login\utils.py", line 89, in expand_login_view
    return url_for(login_view)
  File "d:\microblog\flask\lib\site-packages\flask\helpers.py", line 356, in url_for
    return appctx.app.handle_url_build_error(error, endpoint, values)
  File "d:\microblog\flask\lib\site-packages\flask\app.py", line 2061, in handle_url_build_error
    reraise(exc_type, exc_value, tb)
  File "d:\microblog\flask\lib\site-packages\flask\_compat.py", line 35, in reraise
    raise value
  File "d:\microblog\flask\lib\site-packages\flask\helpers.py", line 345, in url_for
    force_external=external)
  File "d:\microblog\flask\lib\site-packages\werkzeug\routing.py", line 1776, in build
    raise BuildError(endpoint, values, method, self)
werkzeug.routing.BuildError: Could not build url for endpoint 'login'. Did you mean 'auth.login' instead?
2018-05-11 16:26:52,125 [ERROR] app.py(1761):Exception on /auth/login [GET]
Traceback (most recent call last):
  File "d:\microblog\flask\lib\site-packages\flask\app.py", line 2292, in wsgi_app
    response = self.full_dispatch_request()
  File "d:\microblog\flask\lib\site-packages\flask\app.py", line 1815, in full_dispatch_request
    rv = self.handle_user_exception(e)
  File "d:\microblog\flask\lib\site-packages\flask\app.py", line 1718, in handle_user_exception
    reraise(exc_type, exc_value, tb)
  File "d:\microblog\flask\lib\site-packages\flask\_compat.py", line 35, in reraise
    raise value
  File "d:\microblog\flask\lib\site-packages\flask\app.py", line 1813, in full_dispatch_request
    rv = self.dispatch_request()
  File "d:\microblog\flask\lib\site-packages\flask\app.py", line 1799, in dispatch_request
    return self.view_functions[rule.endpoint](**req.view_args)
  File "D:\microblog\app\auth\routes.py", line 41, in login
    return render_template('login.html',title='Sign In',form=form)
  File "d:\microblog\flask\lib\site-packages\flask\templating.py", line 134, in render_template
    return _render(ctx.app.jinja_env.get_or_select_template(template_name_or_list),
  File "d:\microblog\flask\lib\site-packages\jinja2\environment.py", line 869, in get_or_select_template
    return self.get_template(template_name_or_list, parent, globals)
  File "d:\microblog\flask\lib\site-packages\jinja2\environment.py", line 830, in get_template
    return self._load_template(name, self.make_globals(globals))
  File "d:\microblog\flask\lib\site-packages\jinja2\environment.py", line 804, in _load_template
    template = self.loader.load(self, name, globals)
  File "d:\microblog\flask\lib\site-packages\jinja2\loaders.py", line 113, in load
    source, filename, uptodate = self.get_source(environment, name)
  File "d:\microblog\flask\lib\site-packages\flask\templating.py", line 58, in get_source
    return self._get_source_fast(environment, template)
  File "d:\microblog\flask\lib\site-packages\flask\templating.py", line 86, in _get_source_fast
    raise TemplateNotFound(template)
jinja2.exceptions.TemplateNotFound: login.html
2018-05-11 16:27:20,732 [INFO] __init__.py(34):Microblog startup
2018-05-11 16:27:47,457 [INFO] __init__.py(34):Microblog startup
2018-05-11 16:28:49,174 [INFO] __init__.py(34):Microblog startup
2018-05-11 16:28:52,234 [ERROR] app.py(1761):Exception on /auth/login [GET]
Traceback (most recent call last):
  File "d:\microblog\flask\lib\site-packages\flask\app.py", line 2292, in wsgi_app
    response = self.full_dispatch_request()
  File "d:\microblog\flask\lib\site-packages\flask\app.py", line 1815, in full_dispatch_request
    rv = self.handle_user_exception(e)
  File "d:\microblog\flask\lib\site-packages\flask\app.py", line 1718, in handle_user_exception
    reraise(exc_type, exc_value, tb)
  File "d:\microblog\flask\lib\site-packages\flask\_compat.py", line 35, in reraise
    raise value
  File "d:\microblog\flask\lib\site-packages\flask\app.py", line 1813, in full_dispatch_request
    rv = self.dispatch_request()
  File "d:\microblog\flask\lib\site-packages\flask\app.py", line 1799, in dispatch_request
    return self.view_functions[rule.endpoint](**req.view_args)
  File "D:\microblog\app\auth\routes.py", line 41, in login
    return render_template('auth/login.html',title='Sign In',form=form)
  File "d:\microblog\flask\lib\site-packages\flask\templating.py", line 135, in render_template
    context, ctx.app)
  File "d:\microblog\flask\lib\site-packages\flask\templating.py", line 117, in _render
    rv = template.render(context)
  File "d:\microblog\flask\lib\site-packages\jinja2\asyncsupport.py", line 76, in render
    return original_render(self, *args, **kwargs)
  File "d:\microblog\flask\lib\site-packages\jinja2\environment.py", line 1008, in render
    return self.environment.handle_exception(exc_info, True)
  File "d:\microblog\flask\lib\site-packages\jinja2\environment.py", line 780, in handle_exception
    reraise(exc_type, exc_value, tb)
  File "d:\microblog\flask\lib\site-packages\jinja2\_compat.py", line 37, in reraise
    raise value.with_traceback(tb)
  File "D:\microblog\app\templates\auth\login.html", line 1, in top-level template code
    {% extends "base.html" %}
  File "D:\microblog\app\templates\base.html", line 20, in top-level template code
    <a class="nav-link" href="{{ url_for('login') }}">Login</a>
  File "d:\microblog\flask\lib\site-packages\flask\helpers.py", line 356, in url_for
    return appctx.app.handle_url_build_error(error, endpoint, values)
  File "d:\microblog\flask\lib\site-packages\flask\app.py", line 2061, in handle_url_build_error
    reraise(exc_type, exc_value, tb)
  File "d:\microblog\flask\lib\site-packages\flask\_compat.py", line 35, in reraise
    raise value
  File "d:\microblog\flask\lib\site-packages\flask\helpers.py", line 345, in url_for
    force_external=external)
  File "d:\microblog\flask\lib\site-packages\werkzeug\routing.py", line 1776, in build
    raise BuildError(endpoint, values, method, self)
werkzeug.routing.BuildError: Could not build url for endpoint 'login'. Did you mean 'auth.login' instead?
2018-05-11 16:29:09,771 [INFO] __init__.py(34):Microblog startup
