2018-05-12 09:09:37,636 [INFO] __init__.py(40):Microblog startup
2018-05-12 09:10:02,704 [INFO] __init__.py(40):Microblog startup
2018-05-12 09:10:07,469 [INFO] __init__.py(40):Microblog startup
2018-05-12 09:10:28,480 [INFO] __init__.py(40):Microblog startup
2018-05-12 09:10:46,741 [INFO] __init__.py(40):Microblog startup
2018-05-12 09:10:52,485 [INFO] __init__.py(40):Microblog startup
2018-05-12 10:42:18,485 [INFO] __init__.py(40):Microblog startup
2018-05-12 10:49:56,938 [INFO] __init__.py(40):Microblog startup
2018-05-12 11:45:53,544 [INFO] __init__.py(40):Microblog startup
2018-05-12 11:46:02,105 [ERROR] app.py(1761):Exception on /explore [GET]
Traceback (most recent call last):
  File "e:\workspace\flask\flask\app.py", line 2292, in wsgi_app
    response = self.full_dispatch_request()
  File "e:\workspace\flask\flask\app.py", line 1815, in full_dispatch_request
    rv = self.handle_user_exception(e)
  File "e:\workspace\flask\flask\app.py", line 1718, in handle_user_exception
    reraise(exc_type, exc_value, tb)
  File "e:\workspace\flask\flask\_compat.py", line 35, in reraise
    raise value
  File "e:\workspace\flask\flask\app.py", line 1813, in full_dispatch_request
    rv = self.dispatch_request()
  File "e:\workspace\flask\flask\app.py", line 1799, in dispatch_request
    return self.view_functions[rule.endpoint](**req.view_args)
  File "e:\programfiles\anaconda3\lib\site-packages\flask_login\utils.py", line 261, in decorated_view
    return func(*args, **kwargs)
  File "E:\workspace\microblog3\microblog\app\routes.py", line 39, in explore
    return render_template('index.html', title='Explore', posts=posts, prev_url=prev_url, next_url=next_url)
  File "e:\workspace\flask\flask\templating.py", line 135, in render_template
    context, ctx.app)
  File "e:\workspace\flask\flask\templating.py", line 117, in _render
    rv = template.render(context)
  File "e:\programfiles\anaconda3\lib\site-packages\jinja2\asyncsupport.py", line 76, in render
    return original_render(self, *args, **kwargs)
  File "e:\programfiles\anaconda3\lib\site-packages\jinja2\environment.py", line 1008, in render
    return self.environment.handle_exception(exc_info, True)
  File "e:\programfiles\anaconda3\lib\site-packages\jinja2\environment.py", line 780, in handle_exception
    reraise(exc_type, exc_value, tb)
  File "e:\programfiles\anaconda3\lib\site-packages\jinja2\_compat.py", line 37, in reraise
    raise value.with_traceback(tb)
  File "E:\workspace\microblog3\microblog\app\templates\index.html", line 2, in top-level template code
    {% import 'bootstrap/wtf.html' as wtf %}
  File "E:\workspace\microblog3\microblog\app\templates\base.html", line 1, in top-level template code
    {% extends 'bootstrap/base.html' %}
  File "e:\programfiles\anaconda3\lib\site-packages\flask_bootstrap\templates\bootstrap\base.html", line 1, in top-level template code
    {% block doc -%}
  File "e:\programfiles\anaconda3\lib\site-packages\flask_bootstrap\templates\bootstrap\base.html", line 4, in block "doc"
    {%- block html %}
  File "e:\programfiles\anaconda3\lib\site-packages\flask_bootstrap\templates\bootstrap\base.html", line 20, in block "html"
    {% block body -%}
  File "e:\programfiles\anaconda3\lib\site-packages\flask_bootstrap\templates\bootstrap\base.html", line 23, in block "body"
    {% block content -%}
  File "E:\workspace\microblog3\microblog\app\templates\base.html", line 51, in block "content"
    {% block app_content %}{% endblock %}
  File "E:\workspace\microblog3\microblog\app\templates\index.html", line 11, in block "app_content"
    {% for post in posts %}
TypeError: 'Pagination' object is not iterable
2018-05-12 11:48:11,563 [INFO] __init__.py(40):Microblog startup
2018-05-12 11:55:29,102 [INFO] __init__.py(40):Microblog startup
2018-05-12 11:57:47,797 [INFO] __init__.py(40):Microblog startup
2018-05-12 11:58:07,188 [ERROR] app.py(1761):Exception on /user/ericguanwy [GET]
Traceback (most recent call last):
  File "e:\workspace\flask\flask\app.py", line 2292, in wsgi_app
    response = self.full_dispatch_request()
  File "e:\workspace\flask\flask\app.py", line 1815, in full_dispatch_request
    rv = self.handle_user_exception(e)
  File "e:\workspace\flask\flask\app.py", line 1718, in handle_user_exception
    reraise(exc_type, exc_value, tb)
  File "e:\workspace\flask\flask\_compat.py", line 35, in reraise
    raise value
  File "e:\workspace\flask\flask\app.py", line 1813, in full_dispatch_request
    rv = self.dispatch_request()
  File "e:\workspace\flask\flask\app.py", line 1799, in dispatch_request
    return self.view_functions[rule.endpoint](**req.view_args)
  File "e:\programfiles\anaconda3\lib\site-packages\flask_login\utils.py", line 261, in decorated_view
    return func(*args, **kwargs)
  File "E:\workspace\microblog3\microblog\app\routes.py", line 63, in user
    next_url = url_for('user', user=user, page=posts.next_num) if posts.has_next else None
  File "e:\workspace\flask\flask\helpers.py", line 356, in url_for
    return appctx.app.handle_url_build_error(error, endpoint, values)
  File "e:\workspace\flask\flask\app.py", line 2061, in handle_url_build_error
    reraise(exc_type, exc_value, tb)
  File "e:\workspace\flask\flask\_compat.py", line 35, in reraise
    raise value
  File "e:\workspace\flask\flask\helpers.py", line 345, in url_for
    force_external=external)
  File "e:\programfiles\anaconda3\lib\site-packages\werkzeug\routing.py", line 1776, in build
    raise BuildError(endpoint, values, method, self)
werkzeug.routing.BuildError: Could not build url for endpoint 'user' with values ['page', 'user']. Did you forget to specify values ['username']?
2018-05-12 12:00:14,967 [INFO] __init__.py(40):Microblog startup
2018-05-12 12:01:17,735 [INFO] __init__.py(40):Microblog startup
2018-05-12 12:08:05,534 [INFO] __init__.py(40):Microblog startup
2018-05-12 12:09:12,375 [INFO] __init__.py(40):Microblog startup
2018-05-12 12:11:31,392 [INFO] __init__.py(40):Microblog startup
2018-05-12 12:14:57,756 [INFO] __init__.py(40):Microblog startup
2018-05-12 12:16:39,235 [INFO] __init__.py(40):Microblog startup
2018-05-12 21:14:51,758 [INFO] __init__.py(40):Microblog startup
2018-05-12 21:29:29,334 [INFO] __init__.py(41):Microblog startup
2018-05-12 21:29:34,897 [ERROR] app.py(1761):Exception on /explore [GET]
Traceback (most recent call last):
  File "e:\workspace\flask\flask\app.py", line 2292, in wsgi_app
    response = self.full_dispatch_request()
  File "e:\workspace\flask\flask\app.py", line 1815, in full_dispatch_request
    rv = self.handle_user_exception(e)
  File "e:\workspace\flask\flask\app.py", line 1718, in handle_user_exception
    reraise(exc_type, exc_value, tb)
  File "e:\workspace\flask\flask\_compat.py", line 35, in reraise
    raise value
  File "e:\workspace\flask\flask\app.py", line 1813, in full_dispatch_request
    rv = self.dispatch_request()
  File "e:\workspace\flask\flask\app.py", line 1799, in dispatch_request
    return self.view_functions[rule.endpoint](**req.view_args)
  File "e:\programfiles\anaconda3\lib\site-packages\flask_login\utils.py", line 261, in decorated_view
    return func(*args, **kwargs)
  File "E:\workspace\microblog3\microblog\app\routes.py", line 39, in explore
    return render_template('index.html', title='Explore', posts=posts.items, prev_url=prev_url, next_url=next_url)
  File "e:\workspace\flask\flask\templating.py", line 135, in render_template
    context, ctx.app)
  File "e:\workspace\flask\flask\templating.py", line 117, in _render
    rv = template.render(context)
  File "e:\programfiles\anaconda3\lib\site-packages\jinja2\asyncsupport.py", line 76, in render
    return original_render(self, *args, **kwargs)
  File "e:\programfiles\anaconda3\lib\site-packages\jinja2\environment.py", line 1008, in render
    return self.environment.handle_exception(exc_info, True)
  File "e:\programfiles\anaconda3\lib\site-packages\jinja2\environment.py", line 780, in handle_exception
    reraise(exc_type, exc_value, tb)
  File "e:\programfiles\anaconda3\lib\site-packages\jinja2\_compat.py", line 37, in reraise
    raise value.with_traceback(tb)
  File "E:\workspace\microblog3\microblog\app\templates\index.html", line 2, in top-level template code
    {% import 'bootstrap/wtf.html' as wtf %}
  File "E:\workspace\microblog3\microblog\app\templates\base.html", line 1, in top-level template code
    {% extends 'bootstrap/base.html' %}
  File "e:\programfiles\anaconda3\lib\site-packages\flask_bootstrap\templates\bootstrap\base.html", line 1, in top-level template code
    {% block doc -%}
  File "e:\programfiles\anaconda3\lib\site-packages\flask_bootstrap\templates\bootstrap\base.html", line 4, in block "doc"
    {%- block html %}
  File "e:\programfiles\anaconda3\lib\site-packages\flask_bootstrap\templates\bootstrap\base.html", line 20, in block "html"
    {% block body -%}
  File "e:\programfiles\anaconda3\lib\site-packages\flask_bootstrap\templates\bootstrap\base.html", line 23, in block "body"
    {% block content -%}
  File "E:\workspace\microblog3\microblog\app\templates\base.html", line 56, in block "content"
    {% block app_content %}{% endblock %}
  File "E:\workspace\microblog3\microblog\app\templates\index.html", line 12, in block "app_content"
    {% include 'posts.html' %}
  File "E:\workspace\microblog3\microblog\app\templates\posts.html", line 10, in top-level template code
    said {{ moment(post.timestamp).fromnow() }}:
jinja2.exceptions.UndefinedError: 'flask_moment._moment object' has no attribute 'fromnow'
2018-05-12 21:29:58,803 [INFO] __init__.py(41):Microblog startup
2018-05-12 21:43:11,006 [INFO] __init__.py(47):Microblog startup
2018-05-12 21:43:52,386 [INFO] __init__.py(47):Microblog startup
