2018-05-12 00:24:23,984 [ERROR] app.py(1560):Exception on /index [GET]
Traceback (most recent call last):
  File "E:\ProgramFiles\Anaconda3\lib\site-packages\flask\app.py", line 1982, in wsgi_app
    response = self.full_dispatch_request()
  File "E:\ProgramFiles\Anaconda3\lib\site-packages\flask\app.py", line 1614, in full_dispatch_request
    rv = self.handle_user_exception(e)
  File "E:\ProgramFiles\Anaconda3\lib\site-packages\flask\app.py", line 1517, in handle_user_exception
    reraise(exc_type, exc_value, tb)
  File "E:\ProgramFiles\Anaconda3\lib\site-packages\flask\_compat.py", line 33, in reraise
    raise value
  File "E:\ProgramFiles\Anaconda3\lib\site-packages\flask\app.py", line 1612, in full_dispatch_request
    rv = self.dispatch_request()
  File "E:\ProgramFiles\Anaconda3\lib\site-packages\flask\app.py", line 1598, in dispatch_request
    return self.view_functions[rule.endpoint](**req.view_args)
  File "E:\ProgramFiles\Anaconda3\lib\site-packages\flask_login\utils.py", line 261, in decorated_view
    return func(*args, **kwargs)
  File "E:\workspace\microblog3\microblog\app\routes.py", line 24, in index
    posts = user.followed_posts()
  File "E:\workspace\microblog3\microblog\app\models.py", line 52, in followed_posts
    own = Post.query.filter_by(user_id == self.id)
NameError: name 'user_id' is not defined
2018-05-12 00:24:26,994 [ERROR] app.py(1560):Exception on /index [GET]
Traceback (most recent call last):
  File "E:\ProgramFiles\Anaconda3\lib\site-packages\flask\app.py", line 1982, in wsgi_app
    response = self.full_dispatch_request()
  File "E:\ProgramFiles\Anaconda3\lib\site-packages\flask\app.py", line 1614, in full_dispatch_request
    rv = self.handle_user_exception(e)
  File "E:\ProgramFiles\Anaconda3\lib\site-packages\flask\app.py", line 1517, in handle_user_exception
    reraise(exc_type, exc_value, tb)
  File "E:\ProgramFiles\Anaconda3\lib\site-packages\flask\_compat.py", line 33, in reraise
    raise value
  File "E:\ProgramFiles\Anaconda3\lib\site-packages\flask\app.py", line 1612, in full_dispatch_request
    rv = self.dispatch_request()
  File "E:\ProgramFiles\Anaconda3\lib\site-packages\flask\app.py", line 1598, in dispatch_request
    return self.view_functions[rule.endpoint](**req.view_args)
  File "E:\ProgramFiles\Anaconda3\lib\site-packages\flask_login\utils.py", line 261, in decorated_view
    return func(*args, **kwargs)
  File "E:\workspace\microblog3\microblog\app\routes.py", line 24, in index
    posts = user.followed_posts()
  File "E:\workspace\microblog3\microblog\app\models.py", line 52, in followed_posts
    own = Post.query.filter_by(user_id == self.id)
NameError: name 'user_id' is not defined
2018-05-12 00:25:23,529 [INFO] __init__.py(40):Microblog startup
2018-05-12 00:25:28,079 [ERROR] app.py(1560):Exception on /index [GET]
Traceback (most recent call last):
  File "E:\ProgramFiles\Anaconda3\lib\site-packages\flask\app.py", line 1982, in wsgi_app
    response = self.full_dispatch_request()
  File "E:\ProgramFiles\Anaconda3\lib\site-packages\flask\app.py", line 1614, in full_dispatch_request
    rv = self.handle_user_exception(e)
  File "E:\ProgramFiles\Anaconda3\lib\site-packages\flask\app.py", line 1517, in handle_user_exception
    reraise(exc_type, exc_value, tb)
  File "E:\ProgramFiles\Anaconda3\lib\site-packages\flask\_compat.py", line 33, in reraise
    raise value
  File "E:\ProgramFiles\Anaconda3\lib\site-packages\flask\app.py", line 1612, in full_dispatch_request
    rv = self.dispatch_request()
  File "E:\ProgramFiles\Anaconda3\lib\site-packages\flask\app.py", line 1598, in dispatch_request
    return self.view_functions[rule.endpoint](**req.view_args)
  File "E:\ProgramFiles\Anaconda3\lib\site-packages\flask_login\utils.py", line 261, in decorated_view
    return func(*args, **kwargs)
  File "E:\workspace\microblog3\microblog\app\routes.py", line 24, in index
    posts = user.followed_posts()
  File "E:\workspace\microblog3\microblog\app\models.py", line 52, in followed_posts
    own = Post.query.filter_by(Post.user_id == self.id)
TypeError: filter_by() takes 1 positional argument but 2 were given
2018-05-12 00:27:26,298 [INFO] __init__.py(40):Microblog startup
2018-05-12 00:27:31,062 [ERROR] app.py(1560):Exception on /index [GET]
Traceback (most recent call last):
  File "E:\ProgramFiles\Anaconda3\lib\site-packages\flask\app.py", line 1982, in wsgi_app
    response = self.full_dispatch_request()
  File "E:\ProgramFiles\Anaconda3\lib\site-packages\flask\app.py", line 1614, in full_dispatch_request
    rv = self.handle_user_exception(e)
  File "E:\ProgramFiles\Anaconda3\lib\site-packages\flask\app.py", line 1517, in handle_user_exception
    reraise(exc_type, exc_value, tb)
  File "E:\ProgramFiles\Anaconda3\lib\site-packages\flask\_compat.py", line 33, in reraise
    raise value
  File "E:\ProgramFiles\Anaconda3\lib\site-packages\flask\app.py", line 1612, in full_dispatch_request
    rv = self.dispatch_request()
  File "E:\ProgramFiles\Anaconda3\lib\site-packages\flask\app.py", line 1598, in dispatch_request
    return self.view_functions[rule.endpoint](**req.view_args)
  File "E:\ProgramFiles\Anaconda3\lib\site-packages\flask_login\utils.py", line 261, in decorated_view
    return func(*args, **kwargs)
  File "E:\workspace\microblog3\microblog\app\routes.py", line 25, in index
    return render_template('index.html',title='Home', user=user, posts=posts, form= form)
  File "E:\ProgramFiles\Anaconda3\lib\site-packages\flask\templating.py", line 133, in render_template
    return _render(ctx.app.jinja_env.get_or_select_template(template_name_or_list),
  File "E:\ProgramFiles\Anaconda3\lib\site-packages\jinja2\environment.py", line 869, in get_or_select_template
    return self.get_template(template_name_or_list, parent, globals)
  File "E:\ProgramFiles\Anaconda3\lib\site-packages\jinja2\environment.py", line 830, in get_template
    return self._load_template(name, self.make_globals(globals))
  File "E:\ProgramFiles\Anaconda3\lib\site-packages\jinja2\environment.py", line 804, in _load_template
    template = self.loader.load(self, name, globals)
  File "E:\ProgramFiles\Anaconda3\lib\site-packages\jinja2\loaders.py", line 125, in load
    code = environment.compile(source, name, filename)
  File "E:\ProgramFiles\Anaconda3\lib\site-packages\jinja2\environment.py", line 591, in compile
    self.handle_exception(exc_info, source_hint=source_hint)
  File "E:\ProgramFiles\Anaconda3\lib\site-packages\jinja2\environment.py", line 780, in handle_exception
    reraise(exc_type, exc_value, tb)
  File "E:\ProgramFiles\Anaconda3\lib\site-packages\jinja2\_compat.py", line 37, in reraise
    raise value.with_traceback(tb)
  File "E:\workspace\microblog3\microblog\app\templates\index.html", line 22, in template
    {% endif %}
  File "E:\ProgramFiles\Anaconda3\lib\site-packages\jinja2\environment.py", line 497, in _parse
    return Parser(self, source, name, encode_filename(filename)).parse()
  File "E:\ProgramFiles\Anaconda3\lib\site-packages\jinja2\parser.py", line 896, in parse
    result = nodes.Template(self.subparse(), lineno=1)
  File "E:\ProgramFiles\Anaconda3\lib\site-packages\jinja2\parser.py", line 878, in subparse
    rv = self.parse_statement()
  File "E:\ProgramFiles\Anaconda3\lib\site-packages\jinja2\parser.py", line 130, in parse_statement
    return getattr(self, 'parse_' + self.stream.current.value)()
  File "E:\ProgramFiles\Anaconda3\lib\site-packages\jinja2\parser.py", line 268, in parse_block
    node.body = self.parse_statements(('name:endblock',), drop_needle=True)
  File "E:\ProgramFiles\Anaconda3\lib\site-packages\jinja2\parser.py", line 165, in parse_statements
    result = self.subparse(end_tokens)
  File "E:\ProgramFiles\Anaconda3\lib\site-packages\jinja2\parser.py", line 878, in subparse
    rv = self.parse_statement()
  File "E:\ProgramFiles\Anaconda3\lib\site-packages\jinja2\parser.py", line 130, in parse_statement
    return getattr(self, 'parse_' + self.stream.current.value)()
  File "E:\ProgramFiles\Anaconda3\lib\site-packages\jinja2\parser.py", line 212, in parse_if
    'name:endif'))
  File "E:\ProgramFiles\Anaconda3\lib\site-packages\jinja2\parser.py", line 165, in parse_statements
    result = self.subparse(end_tokens)
  File "E:\ProgramFiles\Anaconda3\lib\site-packages\jinja2\parser.py", line 878, in subparse
    rv = self.parse_statement()
  File "E:\ProgramFiles\Anaconda3\lib\site-packages\jinja2\parser.py", line 130, in parse_statement
    return getattr(self, 'parse_' + self.stream.current.value)()
  File "E:\ProgramFiles\Anaconda3\lib\site-packages\jinja2\parser.py", line 198, in parse_for
    body = self.parse_statements(('name:endfor', 'name:else'))
  File "E:\ProgramFiles\Anaconda3\lib\site-packages\jinja2\parser.py", line 165, in parse_statements
    result = self.subparse(end_tokens)
  File "E:\ProgramFiles\Anaconda3\lib\site-packages\jinja2\parser.py", line 878, in subparse
    rv = self.parse_statement()
  File "E:\ProgramFiles\Anaconda3\lib\site-packages\jinja2\parser.py", line 144, in parse_statement
    self.fail_unknown_tag(token.value, token.lineno)
  File "E:\ProgramFiles\Anaconda3\lib\site-packages\jinja2\parser.py", line 97, in fail_unknown_tag
    return self._fail_ut_eof(name, self._end_token_stack, lineno)
  File "E:\ProgramFiles\Anaconda3\lib\site-packages\jinja2\parser.py", line 90, in _fail_ut_eof
    self.fail(' '.join(message), lineno)
  File "E:\ProgramFiles\Anaconda3\lib\site-packages\jinja2\parser.py", line 59, in fail
    raise exc(msg, lineno, self.name, self.filename)
jinja2.exceptions.TemplateSyntaxError: Encountered unknown tag 'endif'. You probably made a nesting mistake. Jinja is expecting this tag, but currently looking for 'endfor' or 'else'. The innermost block that needs to be closed is 'for'.
2018-05-12 00:28:46,957 [INFO] __init__.py(40):Microblog startup
2018-05-12 00:29:54,969 [INFO] routes.py(22):user nina registered.
